Workbook

Sheet Sheet1
A1: Sample_ID | B1: Group | C1: Gene | D1: Target_Type | E1: Ct_Rep1 | F1: Ct_Rep2 | G1: Ct_Rep3 | H1: Avg_Ct
A2: CTRL_1 | B2: Control | C2: GAPDH | D2: Endogenous control | E2: 19.12 | F2: 19.21 | G2: 19.11 | H2: =AVERAGE(E2:G2) -> 19.146667
A3: CTRL_1 | B3: Control | C3: ACTB | D3: Endogenous control | E3: 19.83 | F3: 19.76 | G3: 19.76 | H3: =AVERAGE(E3:G3) -> 19.783333
A4: CTRL_1 | B4: Control | C4: IL6 | D4: Target | E4: 28.22 | F4: 28.34 | G4: 28.28 | H4: =AVERAGE(E4:G4) -> 28.28
A5: CTRL_1 | B5: Control | C5: CXCL8 | D5: Target | E5: 27.41 | F5: 27.37 | G5: 27.52 | H5: =AVERAGE(E5:G5) -> 27.433333
A6: CTRL_1 | B6: Control | C6: TNF | D6: Target | E6: 29.38 | F6: 29.37 | G6: 29.44 | H6: =AVERAGE(E6:G6) -> 29.396667
A7: CTRL_1 | B7: Control | C7: NFKB1 | D7: Target | E7: 23.96 | F7: 24.05 | G7: 24.1 | H7: =AVERAGE(E7:G7) -> 24.036667
A8: CTRL_1 | B8: Control | C8: STAT3 | D8: Target | E8: 23.73 | F8: 23.71 | G8: 23.78 | H8: =AVERAGE(E8:G8) -> 23.74
A9: CTRL_1 | B9: Control | C9: MYC | D9: Target | E9: 24.87 | F9: 24.62 | G9: 24.49 | H9: =AVERAGE(E9:G9) -> 24.66
A10: CTRL_1 | B10: Control | C10: CDKN1A | D10: Target | E10: 25.76 | F10: 25.97 | G10: 25.95 | H10: =AVERAGE(E10:G10) -> 25.893333
A11: CTRL_1 | B11: Control | C11: BAX | D11: Target | E11: 26.67 | F11: 26.45 | G11: 26.56 | H11: =AVERAGE(E11:G11) -> 26.56
A12: CTRL_2 | B12: Control | C12: GAPDH | D12: Endogenous control | E12: 19.24 | F12: 19.21 | G12: 19.18 | H12: =AVERAGE(E12:G12) -> 19.21
A13: CTRL_2 | B13: Control | C13: ACTB | D13: Endogenous control | E13: 20.19 | F13: 20.06 | G13: 20.05 | H13: =AVERAGE(E13:G13) -> 20.1
... A121: TRT_6 | B121: Treatment | C121: BAX | D121: Target | E121: 27.06 | F121: 27.12 | G121: 27.19 | H121: =AVERAGE(E121:G121) -> 27.123333

Sheet Analysis
A1: qPCR Relative Expression Analysis — ΔΔCt Method
A3: Table 1: Average Ct per Sample (mean of technical triplicates) + Reference Ct
A4: Sample_ID | B4: Group | C4: GAPDH_Ct | D4: ACTB_Ct | E4: RefCt_GeoMean | F4: IL6_Ct | G4: CXCL8_Ct | H4: TNF_Ct | I4: NFKB1_Ct | J4: STAT3_Ct | K4: MYC_Ct | L4: CDKN1A_Ct | M4: BAX_Ct
A5: CTRL_1 | B5: Control | C5: =AVERAGEIFS(Sheet1!$H$2:$H$121,Sheet1!$A$2:$A$121,$A5,Sheet1!$C$2:$C$121,"GAPDH") -> 19.146667 | D5: =AVERAGEIFS(Sheet1!$H$2:$H$121,Sheet1!$A$2:$A$121,$A5,Sheet1!$C$2:$C$121,"ACTB") -> 19.783333 | E5: =GEOMEAN(C5:D5) -> 19.462397 | F5: =AVERAGEIFS(Sheet1!$H$2:$H$121,Sheet1!$A$2:$A$121,$A5,Sheet1!$C$2:$C$121,"IL6") -> 28.28 | G5: =AVERAGEIFS(Sheet1!$H$2:$H$121,Sheet1!$A$2:$A$121,$A5,Sheet1!$C$2:$C$121,"CXCL8") -> 27.433333 | H5: =AVERAGEIFS(Sheet1!$H$2:$H$121,Sheet1!$A$2:$A$121,$A5,Sheet1!$C$2:$C$121,"TNF") -> 29.396667 | I5: =AVERAGEIFS(Sheet1!$H$2:$H$121,Sheet1!$A$2:$A$121,$A5,Sheet1!$C$2:$C$121,"NFKB1") -> 24.036667 | J5: =AVERAGEIFS(Sheet1!$H$2:$H$121,Sheet1!$A$2:$A$121,$A5,Sheet1!$C$2:$C$121,"STAT3") -> 23.74 | K5: =AVERAGEIFS(Sheet1!$H$2:$H$121,Sheet1!$A$2:$A$121,$A5,Sheet1!$C$2:$C$121,"MYC") -> 24.66 | L5: =AVERAGEIFS(Sheet1!$H$2:$H$121,Sheet1!$A$2:$A$121,$A5,Sheet1!$C$2:$C$121,"CDKN1A") -> 25.893333 | M5: =AVERAGEIFS(Sheet1!$H$2:$H$121,Sheet1!$A$2:$A$121,$A5,Sheet1!$C$2:$C$121,"BAX") -> 26.56
A6: CTRL_2 | B6: Control | C6: =AVERAGEIFS(Sheet1!$H$2:$H$121,Sheet1!$A$2:$A$121,$A6,Sheet1!$C$2:$C$121,"GAPDH") -> 19.21 | D6: =AVERAGEIFS(Sheet1!$H$2:$H$121,Sheet1!$A$2:$A$121,$A6,Sheet1!$C$2:$C$121,"ACTB") -> 20.1 | E6: =GEOMEAN(C6:D6) -> 19.649962 | F6: =AVERAGEIFS(Sheet1!$H$2:$H$121,Sheet1!$A$2:$A$121,$A6,Sheet1!$C$2:$C$121,"IL6") -> 28.073333 | G6: =AVERAGEIFS(Sheet1!$H$2:$H$121,Sheet1!$A$2:$A$121,$A6,Sheet1!$C$2:$C$121,"CXCL8") -> 27.2 | H6: =AVERAGEIFS(Sheet1!$H$2:$H$121,Sheet1!$A$2:$A$121,$A6,Sheet1!$C$2:$C$121,"TNF") -> 29.166667 | I6: =AVERAGEIFS(Sheet1!$H$2:$H$121,Sheet1!$A$2:$A$121,$A6,Sheet1!$C$2:$C$121,"NFKB1") -> 23.923333 | J6: =AVERAGEIFS(Sheet1!$H$2:$H$121,Sheet1!$A$2:$A$121,$A6,Sheet1!$C$2:$C$121,"STAT3") -> 23.756667 | K6: =AVERAGEIFS(Sheet1!$H$2:$H$121,Sheet1!$A$2:$A$121,$A6,Sheet1!$C$2:$C$121,"MYC") -> 25.396667 | L6: =AVERAGEIFS(Sheet1!$H$2:$H$121,Sheet1!$A$2:$A$121,$A6,Sheet1!$C$2:$C$121,"CDKN1A") -> 25.82 | M6: =AVERAGEIFS(Sheet1!$H$2:$H$121,Sheet1!$A$2:$A$121,$A6,Sheet1!$C$2:$C$121,"BAX") -> 26.886667
A7: CTRL_3 | B7: Control | C7: =AVERAGEIFS(Sheet1!$H$2:$H$121,Sheet1!$A$2:$A$121,$A7,Sheet1!$C$2:$C$121,"GAPDH") -> 18.53 | D7: =AVERAGEIFS(Sheet1!$H$2:$H$121,Sheet1!$A$2:$A$121,$A7,Sheet1!$C$2:$C$121,"ACTB") -> 19.64 | E7: =GEOMEAN(C7:D7) -> 19.076928 | F7: =AVERAGEIFS(Sheet1!$H$2:$H$121,Sheet1!$A$2:$A$121,$A7,Sheet1!$C$2:$C$121,"IL6") -> 27.976667 | G7: =AVERAGEIFS(Sheet1!$H$2:$H$121,Sheet1!$A$2:$A$121,$A7,Sheet1!$C$2:$C$121,"CXCL8") -> 27.23 | H7: =AVERAGEIFS(Sheet1!$H$2:$H$121,Sheet1!$A$2:$A$121,$A7,Sheet1!$C$2:$C$121,"TNF") -> 28.416667 | I7: =AVERAGEIFS(Sheet1!$H$2:$H$121,Sheet1!$A$2:$A$121,$A7,Sheet1!$C$2:$C$121,"NFKB1") -> 23.706667 | J7: =AVERAGEIFS(Sheet1!$H$2:$H$121,Sheet1!$A$2:$A$121,$A7,Sheet1!$C$2:$C$121,"STAT3") -> 23.46 | K7: =AVERAGEIFS(Sheet1!$H$2:$H$121,Sheet1!$A$2:$A$121,$A7,Sheet1!$C$2:$C$121,"MYC") -> 24.553333 | L7: =AVERAGEIFS(Sheet1!$H$2:$H$121,Sheet1!$A$2:$A$121,$A7,Sheet1!$C$2:$C$121,"CDKN1A") -> 25.266667 | M7: =AVERAGEIFS(Sheet1!$H$2:$H$121,Sheet1!$A$2:$A$121,$A7,Sheet1!$C$2:$C$121,"BAX") -> 26.33
A8: CTRL_4 | B8: Control | C8: =AVERAGEIFS(Sheet1!$H$2:$H$121,Sheet1!$A$2:$A$121,$A8,Sheet1!$C$2:$C$121,"GAPDH") -> 19.12 | D8: =AVERAGEIFS(Sheet1!$H$2:$H$121,Sheet1!$A$2:$A$121,$A8,Sheet1!$C$2:$C$121,"ACTB") -> 19.963333 | E8: =GEOMEAN(C8:D8) -> 19.537117 | F8: =AVERAGEIFS(Sheet1!$H$2:$H$121,Sheet1!$A$2:$A$121,$A8,Sheet1!$C$2:$C$121,"IL6") -> 28.416667 | G8: =AVERAGEIFS(Sheet1!$H$2:$H$121,Sheet1!$A$2:$A$121,$A8,Sheet1!$C$2:$C$121,"CXCL8") -> 27.663333 | H8: =AVERAGEIFS(Sheet1!$H$2:$H$121,Sheet1!$A$2:$A$121,$A8,Sheet1!$C$2:$C$121,"TNF") -> 28.343333 | I8: =AVERAGEIFS(Sheet1!$H$2:$H$121,Sheet1!$A$2:$A$121,$A8,Sheet1!$C$2:$C$121,"NFKB1") -> 23.9 | J8: =AVERAGEIFS(Sheet1!$H$2:$H$121,Sheet1!$A$2:$A$121,$A8,Sheet1!$C$2:$C$121,"STAT3") -> 23.633333 | K8: =AVERAGEIFS(Sheet1!$H$2:$H$121,Sheet1!$A$2:$A$121,$A8,Sheet1!$C$2:$C$121,"MYC") -> 24.563333 | L8: =AVERAGEIFS(Sheet1!$H$2:$H$121,Sheet1!$A$2:$A$121,$A8,Sheet1!$C$2:$C$121,"CDKN1A") -> 25.613333 | M8: =AVERAGEIFS(Sheet1!$H$2:$H$121,Sheet1!$A$2:$A$121,$A8,Sheet1!$C$2:$C$121,"BAX") -> 27.19
A9: CTRL_5 | B9: Control | C9: =AVERAGEIFS(Sheet1!$H$2:$H$121,Sheet1!$A$2:$A$121,$A9,Sheet1!$C$2:$C$121,"GAPDH") -> 19.283333 | D9: =AVERAGEIFS(Sheet1!$H$2:$H$121,Sheet1!$A$2:$A$121,$A9,Sheet1!$C$2:$C$121,"ACTB") -> 20.22 | E9: =GEOMEAN(C9:D9) -> 19.746114 | F9: =AVERAGEIFS(Sheet1!$H$2:$H$121,Sheet1!$A$2:$A$121,$A9,Sheet1!$C$2:$C$121,"IL6") -> 28.383333 | G9: =AVERAGEIFS(Sheet1!$H$2:$H$121,Sheet1!$A$2:$A$121,$A9,Sheet1!$C$2:$C$121,"CXCL8") -> 27.733333 | H9: =AVERAGEIFS(Sheet1!$H$2:$H$121,Sheet1!$A$2:$A$121,$A9,Sheet1!$C$2:$C$121,"TNF") -> 28.58 | I9: =AVERAGEIFS(Sheet1!$H$2:$H$121,Sheet1!$A$2:$A$121,$A9,Sheet1!$C$2:$C$121,"NFKB1") -> 24.746667 | J9: =AVERAGEIFS(Sheet1!$H$2:$H$121,Sheet1!$A$2:$A$121,$A9,Sheet1!$C$2:$C$121,"STAT3") -> 24.18 | K9: =AVERAGEIFS(Sheet1!$H$2:$H$121,Sheet1!$A$2:$A$121,$A9,Sheet1!$C$2:$C$121,"MYC") -> 25.936667 | L9: =AVERAGEIFS(Sheet1!$H$2:$H$121,Sheet1!$A$2:$A$121,$A9,Sheet1!$C$2:$C$121,"CDKN1A") -> 26.303333 | M9: =AVERAGEIFS(Sheet1!$H$2:$H$121,Sheet1!$A$2:$A$121,$A9,Sheet1!$C$2:$C$121,"BAX") -> 26.893333
A10: CTRL_6 | B10: Control | C10: =AVERAGEIFS(Sheet1!$H$2:$H$121,Sheet1!$A$2:$A$121,$A10,Sheet1!$C$2:$C$121,"GAPDH") -> 19.17 | D10: =AVERAGEIFS(Sheet1!$H$2:$H$121,Sheet1!$A$2:$A$121,$A10,Sheet1!$C$2:$C$121,"ACTB") -> 20.13 | E10: =GEOMEAN(C10:D10) -> 19.644137 | F10: =AVERAGEIFS(Sheet1!$H$2:$H$121,Sheet1!$A$2:$A$121,$A10,Sheet1!$C$2:$C$121,"IL6") -> 29.113333 | G10: =AVERAGEIFS(Sheet1!$H$2:$H$121,Sheet1!$A$2:$A$121,$A10,Sheet1!$C$2:$C$121,"CXCL8") -> 27.736667 | H10: =AVERAGEIFS(Sheet1!$H$2:$H$121,Sheet1!$A$2:$A$121,$A10,Sheet1!$C$2:$C$121,"TNF") -> 28.553333 | I10: =AVERAGEIFS(Sheet1!$H$2:$H$121,Sheet1!$A$2:$A$121,$A10,Sheet1!$C$2:$C$121,"NFKB1") -> 24.033333 | J10: =AVERAGEIFS(Sheet1!$H$2:$H$121,Sheet1!$A$2:$A$121,$A10,Sheet1!$C$2:$C$121,"STAT3") -> 23.926667 | K10: =AVERAGEIFS(Sheet1!$H$2:$H$121,Sheet1!$A$2:$A$121,$A10,Sheet1!$C$2:$C$121,"MYC") -> 25.256667 | L10: =AVERAGEIFS(Sheet1!$H$2:$H$121,Sheet1!$A$2:$A$121,$A10,Sheet1!$C$2:$C$121,"CDKN1A") -> 25.7 | M10: =AVERAGEIFS(Sheet1!$H$2:$H$121,Sheet1!$A$2:$A$121,$A10,Sheet1!$C$2:$C$121,"BAX") -> 26.343333
A11: TRT_1 | B11: Treatment | C11: =AVERAGEIFS(Sheet1!$H$2:$H$121,Sheet1!$A$2:$A$121,$A11,Sheet1!$C$2:$C$121,"GAPDH") -> 19.376667 | D11: =AVERAGEIFS(Sheet1!$H$2:$H$121,Sheet1!$A$2:$A$121,$A11,Sheet1!$C$2:$C$121,"ACTB") -> 20.533333 | E11: =GEOMEAN(C11:D11) -> 19.946618 | F11: =AVERAGEIFS(Sheet1!$H$2:$H$121,Sheet1!$A$2:$A$121,$A11,Sheet1!$C$2:$C$121,"IL6") -> 25.236667 | G11: =AVERAGEIFS(Sheet1!$H$2:$H$121,Sheet1!$A$2:$A$121,$A11,Sheet1!$C$2:$C$121,"CXCL8") -> 25.946667 | H11: =AVERAGEIFS(Sheet1!$H$2:$H$121,Sheet1!$A$2:$A$121,$A11,Sheet1!$C$2:$C$121,"TNF") -> 27.446667 | I11: =AVERAGEIFS(Sheet1!$H$2:$H$121,Sheet1!$A$2:$A$121,$A11,Sheet1!$C$2:$C$121,"NFKB1") -> 23.116667 | J11: =AVERAGEIFS(Sheet1!$H$2:$H$121,Sheet1!$A$2:$A$121,$A11,Sheet1!$C$2:$C$121,"STAT3") -> 22.856667 | K11: =AVERAGEIFS(Sheet1!$H$2:$H$121,Sheet1!$A$2:$A$121,$A11,Sheet1!$C$2:$C$121,"MYC") -> 24.303333 | L11: =AVERAGEIFS(Sheet1!$H$2:$H$121,Sheet1!$A$2:$A$121,$A11,Sheet1!$C$2:$C$121,"CDKN1A") -> 28 | M11: =AVERAGEIFS(Sheet1!$H$2:$H$121,Sheet1!$A$2:$A$121,$A11,Sheet1!$C$2:$C$121,"BAX") -> 27.56
A12: TRT_2 | B12: Treatment | C12: =AVERAGEIFS(Sheet1!$H$2:$H$121,Sheet1!$A$2:$A$121,$A12,Sheet1!$C$2:$C$121,"GAPDH") -> 19.103333 | D12: =AVERAGEIFS(Sheet1!$H$2:$H$121,Sheet1!$A$2:$A$121,$A12,Sheet1!$C$2:$C$121,"ACTB") -> 19.783333 | E12: =GEOMEAN(C12:D12) -> 19.44036 | F12: =AVERAGEIFS(Sheet1!$H$2:$H$121,Sheet1!$A$2:$A$121,$A12,Sheet1!$C$2:$C$121,"IL6") -> 25.173333 | G12: =AVERAGEIFS(Sheet1!$H$2:$H$121,Sheet1!$A$2:$A$121,$A12,Sheet1!$C$2:$C$121,"CXCL8") -> 25.38 | H12: =AVERAGEIFS(Sheet1!$H$2:$H$121,Sheet1!$A$2:$A$121,$A12,Sheet1!$C$2:$C$121,"TNF") -> 27.466667 | I12: =AVERAGEIFS(Sheet1!$H$2:$H$121,Sheet1!$A$2:$A$121,$A12,Sheet1!$C$2:$C$121,"NFKB1") -> 23.71 | J12: =AVERAGEIFS(Sheet1!$H$2:$H$121,Sheet1!$A$2:$A$121,$A12,Sheet1!$C$2:$C$121,"STAT3") -> 23.05 | K12: =AVERAGEIFS(Sheet1!$H$2:$H$121,Sheet1!$A$2:$A$121,$A12,Sheet1!$C$2:$C$121,"MYC") -> 23.786667 | L12: =AVERAGEIFS(Sheet1!$H$2:$H$121,Sheet1!$A$2:$A$121,$A12,Sheet1!$C$2:$C$121,"CDKN1A") -> 27.95 | M12: =AVERAGEIFS(Sheet1!$H$2:$H$121,Sheet1!$A$2:$A$121,$A12,Sheet1!$C$2:$C$121,"BAX") -> 28.263333
A13: TRT_3 | B13: Treatment | C13: =AVERAGEIFS(Sheet1!$H$2:$H$121,Sheet1!$A$2:$A$121,$A13,Sheet1!$C$2:$C$121,"GAPDH") -> 19.076667 | D13: =AVERAGEIFS(Sheet1!$H$2:$H$121,Sheet1!$A$2:$A$121,$A13,Sheet1!$C$2:$C$121,"ACTB") -> 20.156667 | E13: =GEOMEAN(C13:D13) -> 19.609233 | F13: =AVERAGEIFS(Sheet1!$H$2:$H$121,Sheet1!$A$2:$A$121,$A13,Sheet1!$C$2:$C$121,"IL6") -> 25.946667 | G13: =AVERAGEIFS(Sheet1!$H$2:$H$121,Sheet1!$A$2:$A$121,$A13,Sheet1!$C$2:$C$121,"CXCL8") -> 25.153333 | H13: =AVERAGEIFS(Sheet1!$H$2:$H$121,Sheet1!$A$2:$A$121,$A13,Sheet1!$C$2:$C$121,"TNF") -> 28.143333 | I13: =AVERAGEIFS(Sheet1!$H$2:$H$121,Sheet1!$A$2:$A$121,$A13,Sheet1!$C$2:$C$121,"NFKB1") -> 23.69 | J13: =AVERAGEIFS(Sheet1!$H$2:$H$121,Sheet1!$A$2:$A$121,$A13,Sheet1!$C$2:$C$121,"STAT3") -> 23.373333 | K13: =AVERAGEIFS(Sheet1!$H$2:$H$121,Sheet1!$A$2:$A$121,$A13,Sheet1!$C$2:$C$121,"MYC") -> 24.276667 | L13: =AVERAGEIFS(Sheet1!$H$2:$H$121,Sheet1!$A$2:$A$121,$A13,Sheet1!$C$2:$C$121,"CDKN1A") -> 27.4 | M13: =AVERAGEIFS(Sheet1!$H$2:$H$121,Sheet1!$A$2:$A$121,$A13,Sheet1!$C$2:$C$121,"BAX") -> 28.41
A14: TRT_4 | B14: Treatment | C14: =AVERAGEIFS(Sheet1!$H$2:$H$121,Sheet1!$A$2:$A$121,$A14,Sheet1!$C$2:$C$121,"GAPDH") -> 18.9 | D14: =AVERAGEIFS(Sheet1!$H$2:$H$121,Sheet1!$A$2:$A$121,$A14,Sheet1!$C$2:$C$121,"ACTB") -> 19.976667 | E14: =GEOMEAN(C14:D14) -> 19.430877 | F14: =AVERAGEIFS(Sheet1!$H$2:$H$121,Sheet1!$A$2:$A$121,$A14,Sheet1!$C$2:$C$121,"IL6") -> 24.993333 | G14: =AVERAGEIFS(Sheet1!$H$2:$H$121,Sheet1!$A$2:$A$121,$A14,Sheet1!$C$2:$C$121,"CXCL8") -> 25.503333 | H14: =AVERAGEIFS(Sheet1!$H$2:$H$121,Sheet1!$A$2:$A$121,$A14,Sheet1!$C$2:$C$121,"TNF") -> 27.703333 | I14: =AVERAGEIFS(Sheet1!$H$2:$H$121,Sheet1!$A$2:$A$121,$A14,Sheet1!$C$2:$C$121,"NFKB1") -> 24.066667 | J14: =AVERAGEIFS(Sheet1!$H$2:$H$121,Sheet1!$A$2:$A$121,$A14,Sheet1!$C$2:$C$121,"STAT3") -> 23.446667 | K14: =AVERAGEIFS(Sheet1!$H$2:$H$121,Sheet1!$A$2:$A$121,$A14,Sheet1!$C$2:$C$121,"MYC") -> 23.85 | L14: =AVERAGEIFS(Sheet1!$H$2:$H$121,Sheet1!$A$2:$A$121,$A14,Sheet1!$C$2:$C$121,"CDKN1A") -> 26.926667 | M14: =AVERAGEIFS(Sheet1!$H$2:$H$121,Sheet1!$A$2:$A$121,$A14,Sheet1!$C$2:$C$121,"BAX") -> 28.113333
A15: TRT_5 | B15: Treatment | C15: =AVERAGEIFS(Sheet1!$H$2:$H$121,Sheet1!$A$2:$A$121,$A15,Sheet1!$C$2:$C$121,"GAPDH") -> 19.136667 | D15: =AVERAGEIFS(Sheet1!$H$2:$H$121,Sheet1!$A$2:$A$121,$A15,Sheet1!$C$2:$C$121,"ACTB") -> 20.34 | E15: =GEOMEAN(C15:D15) -> 19.729161 | F15: =AVERAGEIFS(Sheet1!$H$2:$H$121,Sheet1!$A$2:$A$121,$A15,Sheet1!$C$2:$C$121,"IL6") -> 25.296667 | G15: =AVERAGEIFS(Sheet1!$H$2:$H$121,Sheet1!$A$2:$A$121,$A15,Sheet1!$C$2:$C$121,"CXCL8") -> 25.826667 | H15: =AVERAGEIFS(Sheet1!$H$2:$H$121,Sheet1!$A$2:$A$121,$A15,Sheet1!$C$2:$C$121,"TNF") -> 27.533333 | I15: =AVERAGEIFS(Sheet1!$H$2:$H$121,Sheet1!$A$2:$A$121,$A15,Sheet1!$C$2:$C$121,"NFKB1") -> 24.226667 | J15: =AVERAGEIFS(Sheet1!$H$2:$H$121,Sheet1!$A$2:$A$121,$A15,Sheet1!$C$2:$C$121,"STAT3") -> 23.393333 | K15: =AVERAGEIFS(Sheet1!$H$2:$H$121,Sheet1!$A$2:$A$121,$A15,Sheet1!$C$2:$C$121,"MYC") -> 24.206667 | L15: =AVERAGEIFS(Sheet1!$H$2:$H$121,Sheet1!$A$2:$A$121,$A15,Sheet1!$C$2:$C$121,"CDKN1A") -> 27.353333 | M15: =AVERAGEIFS(Sheet1!$H$2:$H$121,Sheet1!$A$2:$A$121,$A15,Sheet1!$C$2:$C$121,"BAX") -> 27.656667
A16: TRT_6 | B16: Treatment | C16: =AVERAGEIFS(Sheet1!$H$2:$H$121,Sheet1!$A$2:$A$121,$A16,Sheet1!$C$2:$C$121,"GAPDH") -> 18.9 | D16: =AVERAGEIFS(Sheet1!$H$2:$H$121,Sheet1!$A$2:$A$121,$A16,Sheet1!$C$2:$C$121,"ACTB") -> 19.7 | E16: =GEOMEAN(C16:D16) -> 19.295854 | F16: =AVERAGEIFS(Sheet1!$H$2:$H$121,Sheet1!$A$2:$A$121,$A16,Sheet1!$C$2:$C$121,"IL6") -> 25.2 | G16: =AVERAGEIFS(Sheet1!$H$2:$H$121,Sheet1!$A$2:$A$121,$A16,Sheet1!$C$2:$C$121,"CXCL8") -> 24.816667 | H16: =AVERAGEIFS(Sheet1!$H$2:$H$121,Sheet1!$A$2:$A$121,$A16,Sheet1!$C$2:$C$121,"TNF") -> 27.06 | I16: =AVERAGEIFS(Sheet1!$H$2:$H$121,Sheet1!$A$2:$A$121,$A16,Sheet1!$C$2:$C$121,"NFKB1") -> 23.216667 | J16: =AVERAGEIFS(Sheet1!$H$2:$H$121,Sheet1!$A$2:$A$121,$A16,Sheet1!$C$2:$C$121,"STAT3") -> 22.453333 | K16: =AVERAGEIFS(Sheet1!$H$2:$H$121,Sheet1!$A$2:$A$121,$A16,Sheet1!$C$2:$C$121,"MYC") -> 23.816667 | L16: =AVERAGEIFS(Sheet1!$H$2:$H$121,Sheet1!$A$2:$A$121,$A16,Sheet1!$C$2:$C$121,"CDKN1A") -> 27.696667 | M16: =AVERAGEIFS(Sheet1!$H$2:$H$121,Sheet1!$A$2:$A$121,$A16,Sheet1!$C$2:$C$121,"BAX") -> 27.123333
A18: Table 2: ΔCt per Sample (ΔCt = Target_Ct − RefCt_GeoMean)
A19: Sample_ID | B19: Group | C19: IL6 | D19: CXCL8 | E19: TNF | F19: NFKB1 | G19: STAT3 | H19: MYC | I19: CDKN1A | J19: BAX
A20: =A5 -> CTRL_1 | B20: =B5 -> Control | C20: =F5-$E5 -> 8.8176032 | D20: =G5-$E5 -> 7.9709365 | E20: =H5-$E5 -> 9.9342699 | F20: =I5-$E5 -> 4.5742699 | G20: =J5-$E5 -> 4.2776032 | H20: =K5-$E5 -> 5.1976032 | I20: =L5-$E5 -> 6.4309365 | J20: =M5-$E5 -> 7.0976032
A21: =A6 -> CTRL_2 | B21: =B6 -> Control | C21: =F6-$E6 -> 8.4233715 | D21: =G6-$E6 -> 7.5500382 | E21: =H6-$E6 -> 9.5167048 | F21: =I6-$E6 -> 4.2733715 | G21: =J6-$E6 -> 4.1067048 | H21: =K6-$E6 -> 5.7467048 | I21: =L6-$E6 -> 6.1700382 | J21: =M6-$E6 -> 7.2367048
A22: =A7 -> CTRL_3 | B22: =B7 -> Control | C22: =F7-$E7 -> 8.8997382 | D22: =G7-$E7 -> 8.1530715 | E22: =H7-$E7 -> 9.3397382 | F22: =I7-$E7 -> 4.6297382 | G22: =J7-$E7 -> 4.3830715 | H22: =K7-$E7 -> 5.4764049 | I22: =L7-$E7 -> 6.1897382 | J22: =M7-$E7 -> 7.2530715
A23: =A8 -> CTRL_4 | B23: =B8 -> Control | C23: =F8-$E8 -> 8.8795499 | D23: =G8-$E8 -> 8.1262165 | E23: =H8-$E8 -> 8.8062165 | F23: =I8-$E8 -> 4.3628832 | G23: =J8-$E8 -> 4.0962165 | H23: =K8-$E8 -> 5.0262165 | I23: =L8-$E8 -> 6.0762165 | J23: =M8-$E8 -> 7.6528832
A24: =A9 -> CTRL_5 | B24: =B9 -> Control | C24: =F9-$E9 -> 8.6372198 | D24: =G9-$E9 -> 7.9872198 | E24: =H9-$E9 -> 8.8338865 | F24: =I9-$E9 -> 5.0005531 | G24: =J9-$E9 -> 4.4338865 | H24: =K9-$E9 -> 6.1905531 | I24: =L9-$E9 -> 6.5572198 | J24: =M9-$E9 -> 7.1472198
A25: =A10 -> CTRL_6 | B25: =B10 -> Control | C25: =F10-$E10 -> 9.4691968 | D25: =G10-$E10 -> 8.0925301 | E25: =H10-$E10 -> 8.9091968 | F25: =I10-$E10 -> 4.3891968 | G25: =J10-$E10 -> 4.2825301 | H25: =K10-$E10 -> 5.6125301 | I25: =L10-$E10 -> 6.0558635 | J25: =M10-$E10 -> 6.6991968
A26: =A11 -> TRT_1 | B26: =B11 -> Treatment | C26: =F11-$E11 -> 5.290049 | D26: =G11-$E11 -> 6.000049 | E26: =H11-$E11 -> 7.500049 | F26: =I11-$E11 -> 3.170049 | G26: =J11-$E11 -> 2.910049 | H26: =K11-$E11 -> 4.3567157 | I26: =L11-$E11 -> 8.0533824 | J26: =M11-$E11 -> 7.6133824
A27: =A12 -> TRT_2 | B27: =B12 -> Treatment | C27: =F12-$E12 -> 5.732973 | D27: =G12-$E12 -> 5.9396396 | E27: =H12-$E12 -> 8.0263063 | F27: =I12-$E12 -> 4.2696396 | G27: =J12-$E12 -> 3.6096396 | H27: =K12-$E12 -> 4.3463063 | I27: =L12-$E12 -> 8.5096396 | J27: =M12-$E12 -> 8.822973
A28: =A13 -> TRT_3 | B28: =B13 -> Treatment | C28: =F13-$E13 -> 6.3374339 | D28: =G13-$E13 -> 5.5441005 | E28: =H13-$E13 -> 8.5341005 | F28: =I13-$E13 -> 4.0807672 | G28: =J13-$E13 -> 3.7641005 | H28: =K13-$E13 -> 4.6674339 | I28: =L13-$E13 -> 7.7907672 | J28: =M13-$E13 -> 8.8007672
A29: =A14 -> TRT_4 | B29: =B14 -> Treatment | C29: =F14-$E14 -> 5.5624558 | D29: =G14-$E14 -> 6.0724558 | E29: =H14-$E14 -> 8.2724558 | F29: =I14-$E14 -> 4.6357892 | G29: =J14-$E14 -> 4.0157892 | H29: =K14-$E14 -> 4.4191225 | I29: =L14-$E14 -> 7.4957892 | J29: =M14-$E14 -> 8.6824558
A30: =A15 -> TRT_5 | B30: =B15 -> Treatment | C30: =F15-$E15 -> 5.5675055 | D30: =G15-$E15 -> 6.0975055 | E30: =H15-$E15 -> 7.8041722 | F30: =I15-$E15 -> 4.4975055 | G30: =J15-$E15 -> 3.6641722 | H30: =K15-$E15 -> 4.4775055 | I30: =L15-$E15 -> 7.6241722 | J30: =M15-$E15 -> 7.9275055
A31: =A16 -> TRT_6 | B31: =B16 -> Treatment | C31: =F16-$E16 -> 5.9041455 | D31: =G16-$E16 -> 5.5208122 | E31: =H16-$E16 -> 7.7641455 | F31: =I16-$E16 -> 3.9208122 | G31: =J16-$E16 -> 3.1574789 | H31: =K16-$E16 -> 4.5208122 | I31: =L16-$E16 -> 8.4008122 | J31: =M16-$E16 -> 7.8274789
A33: Control Mean ΔCt (baseline) | C33: =AVERAGEIF($B$20:$B$31,"Control",C$20:C$31) -> 8.8544466 | D33: =AVERAGEIF($B$20:$B$31,"Control",D$20:D$31) -> 7.9800021 | E33: =AVERAGEIF($B$20:$B$31,"Control",E$20:E$31) -> 9.2233354 | F33: =AVERAGEIF($B$20:$B$31,"Control",F$20:F$31) -> 4.5383354 | G33: =AVERAGEIF($B$20:$B$31,"Control",G$20:G$31) -> 4.2633354 | H33: =AVERAGEIF($B$20:$B$31,"Control",H$20:H$31) -> 5.5416688 | I33: =AVERAGEIF($B$20:$B$31,"Control",I$20:I$31) -> 6.2466688 | J33: =AVERAGEIF($B$20:$B$31,"Control",J$20:J$31) -> 7.1811132
A36: Table 3: Fold Change per Sample (2^-ΔΔCt, relative to Control mean)
A37: Sample_ID | B37: Group | C37: IL6 | D37: CXCL8 | E37: TNF | F37: NFKB1 | G37: STAT3 | H37: MYC | I37: CDKN1A | J37: BAX
A38: =A20 -> CTRL_1 | B38: =B20 -> Control | C38: =2^-(C20-$C$33) -> 1.0258667 | D38: =2^-(D20-$D$33) -> 1.0063036 | E38: =2^-(E20-$E$33) -> 0.61092432 | F38: =2^-(F20-$F$33) -> 0.97539979 | G38: =2^-(G20-$G$33) -> 0.99015908 | H38: =2^-(H20-$H$33) -> 1.2693286 | I38: =2^-(I20-$I$33) -> 0.88009565 | J38: =2^-(J20-$J$33) -> 1.0595929
A39: =A21 -> CTRL_2 | B39: =B21 -> Control | C39: =2^-(C21-$C$33) -> 1.3482379 | D39: =2^-(D21-$D$33) -> 1.3471999 | E39: =2^-(E21-$E$33) -> 0.81599409 | F39: =2^-(F21-$F$33) -> 1.201606 | G39: =2^-(G21-$G$33) -> 1.1146808 | H39: =2^-(H21-$H$33) -> 0.86751701 | I39: =2^-(I21-$I$33) -> 1.0545523 | J39: =2^-(J21-$J$33) -> 0.96219979
A40: =A22 -> CTRL_3 | B40: =B22 -> Control | C40: =2^-(C22-$C$33) -> 0.9690939 | D40: =2^-(D22-$D$33) -> 0.88695363 | E40: =2^-(E22-$E$33) -> 0.92248493 | F40: =2^-(F22-$F$33) -> 0.93860969 | G40: =2^-(G22-$G$33) -> 0.920356 | H40: =2^-(H22-$H$33) -> 1.0462763 | I40: =2^-(I22-$I$33) -> 1.0402502 | J40: =2^-(J22-$J$33) -> 0.95134577
A41: =A23 -> CTRL_4 | B41: =B23 -> Control | C41: =2^-(C23-$C$33) -> 0.98275023 | D41: =2^-(D23-$D$33) -> 0.90361842 | E41: =2^-(E23-$E$33) -> 1.3352584 | F41: =2^-(F23-$F$33) -> 1.1293184 | G41: =2^-(G23-$G$33) -> 1.122814 | H41: =2^-(H23-$H$33) -> 1.4294422 | I41: =2^-(I23-$I$33) -> 1.1254112 | J41: =2^-(J23-$J$33) -> 0.7210794
A42: =A24 -> CTRL_5 | B42: =B24 -> Control | C42: =2^-(C24-$C$33) -> 1.1624968 | D42: =2^-(D24-$D$33) -> 0.99500958 | E42: =2^-(E24-$E$33) -> 1.309893 | F42: =2^-(F24-$F$33) -> 0.72586961 | G42: =2^-(G24-$G$33) -> 0.88850327 | H42: =2^-(H24-$H$33) -> 0.63777332 | I42: =2^-(I24-$I$33) -> 0.80633374 | J42: =2^-(J24-$J$33) -> 1.0237713
A43: =A25 -> CTRL_6 | B43: =B25 -> Control | C43: =2^-(C25-$C$33) -> 0.65304294 | D43: =2^-(D25-$D$33) -> 0.92496583 | E43: =2^-(E25-$E$33) -> 1.2432691 | F43: =2^-(F25-$F$33) -> 1.1089072 | G43: =2^-(G25-$G$33) -> 0.98678337 | H43: =2^-(H25-$H$33) -> 0.9520694 | I43: =2^-(I25-$I$33) -> 1.1414007 | J43: =2^-(J25-$J$33) -> 1.3965976
A44: =A26 -> TRT_1 | B44: =B26 -> Treatment | C44: =2^-(C26-$C$33) -> 11.830159 | D44: =2^-(D26-$D$33) -> 3.9448026 | E44: =2^-(E26-$E$33) -> 3.3018771 | F44: =2^-(F26-$F$33) -> 2.5816375 | G44: =2^-(G26-$G$33) -> 2.5549347 | H44: =2^-(H26-$H$33) -> 2.27356 | I44: =2^-(I26-$I$33) -> 0.28584133 | J44: =2^-(J26-$J$33) -> 0.74109524
A45: =A27 -> TRT_2 | B45: =B27 -> Treatment | C45: =2^-(C27-$C$33) -> 8.7027635 | D45: =2^-(D27-$D$33) -> 4.1134887 | E45: =2^-(E27-$E$33) -> 2.2926707 | F45: =2^-(F27-$F$33) -> 1.2047183 | G45: =2^-(G27-$G$33) -> 1.5731932 | H45: =2^-(H27-$H$33) -> 2.2900236 | I45: =2^-(I27-$I$33) -> 0.20834251 | J45: =2^-(J27-$J$33) -> 0.32044313
...

Sheet Results
A1: qPCR Statistical Analysis — Mann-Whitney U Test on ΔCt (Control vs Treatment)
A2: Normal approximation with continuity correction; Benjamini-Hochberg FDR correction across 8 genes. Fold change via ΔΔCt method.
A4: Gene | B4: n_Control | C4: n_Treatment | D4: RankSum_Control (R1) | E4: U1 | F4: U2 | G4: U | H4: Mean_U | I4: SD_U | J4: z | K4: p_value | L4: BH_Rank | M4: BH_raw | N4: q_value (FDR) | O4: Sig. | P4: Mean_FC_Control | Q4: SEM_FC_Control | R4: Mean_FC_Treatment | S4: SEM_FC_Treatment | T4: log2FC (Trt vs Ctrl) | V4: Gene | W4: Control | X4: Treatment | Y4: SEM_Control | Z4: SEM_Treatment | AB4: Gene | AC4: log2FC
A5: IL6 | B5: =COUNTIF(Analysis!$B$20:$B$31,"Control") -> 6 | C5: =COUNTIF(Analysis!$B$20:$B$31,"Treatment") -> 6 | D5: =SUM(INDEX(Analysis!$C$53:$J$58,0,MATCH($A5,Analysis!$C$52:$J$52,0))) -> 57 | E5: =D5-B5*(B5+1)/2 -> 36 | F5: =B5*C5-E5 -> 0 | G5: =MIN(E5,F5) -> 0 | H5: =B5*C5/2 -> 18 | I5: =SQRT(B5*C5*(B5+C5+1)/12) -> 6.244998 | J5: =(G5-H5-0.5*SIGN(G5-H5))/I5 -> -2.8022427 | K5: =2*(1-_xlfn.NORM.S.DIST(ABS(J5),TRUE)) -> 0.0050748681 | L5: =_xlfn.RANK.EQ(K5,$K$5:$K$12,1)+COUNTIF($K$5:K5,K5)-1 -> 1 | M5: =K5*8/L5 -> 0.040598945 | N5: =_xlfn.MINIFS($M$5:$M$12,$L$5:$L$12,">="&L5) -> 0.0067664908 | O5: =IF(N5<0.001,"***",IF(N5<0.01,"**",IF(N5<0.05,"*","ns"))) -> ** | P5: =AVERAGE(INDEX(Analysis!$C$38:$J$43,0,MATCH($A5,Analysis!$C$37:$J$37,0))) -> 1.0235814 | Q5: =STDEV(INDEX(Analysis!$C$38:$J$43,0,MATCH($A5,Analysis!$C$37:$J$37,0)))/SQRT(B5) -> 0.094276078 | R5: =AVERAGE(INDEX(Analysis!$C$44:$J$49,0,MATCH($A5,Analysis!$C$37:$J$37,0))) -> 8.9235026 | S5: =STDEV(INDEX(Analysis!$C$44:$J$49,0,MATCH($A5,Analysis!$C$37:$J$37,0)))/SQRT(C5) -> 0.84892731 | T5: =LOG(R5/P5,2) -> 3.1239842 | V5: =A5 -> IL6 | W5: =P5 -> 1.0235814 | X5: =R5 -> 8.9235026 | Y5: =Q5 -> 0.094276078 | Z5: =S5 -> 0.84892731 | AB5: =A5 -> IL6 | AC5: =T5 -> 3.1239842
A6: CXCL8 | B6: =COUNTIF(Analysis!$B$20:$B$31,"Control") -> 6 | C6: =COUNTIF(Analysis!$B$20:$B$31,"Treatment") -> 6 | D6: =SUM(INDEX(Analysis!$C$53:$J$58,0,MATCH($A6,Analysis!$C$52:$J$52,0))) -> 57 | E6: =D6-B6*(B6+1)/2 -> 36 | F6: =B6*C6-E6 -> 0 | G6: =MIN(E6,F6) -> 0 | H6: =B6*C6/2 -> 18 | I6: =SQRT(B6*C6*(B6+C6+1)/12) -> 6.244998 | J6: =(G6-H6-0.5*SIGN(G6-H6))/I6 -> -2.8022427 | K6: =2*(1-_xlfn.NORM.S.DIST(ABS(J6),TRUE)) -> 0.0050748681 | L6: =_xlfn.RANK.EQ(K6,$K$5:$K$12,1)+COUNTIF($K$5:K6,K6)-1 -> 2 | M6: =K6*8/L6 -> 0.020299472 | N6: =_xlfn.MINIFS($M$5:$M$12,$L$5:$L$12,">="&L6) -> 0.0067664908 | O6: =IF(N6<0.001,"***",IF(N6<0.01,"**",IF(N6<0.05,"*","ns"))) -> ** | P6: =AVERAGE(INDEX(Analysis!$C$38:$J$43,0,MATCH($A6,Analysis!$C$37:$J$37,0))) -> 1.0106752 | Q6: =STDEV(INDEX(Analysis!$C$38:$J$43,0,MATCH($A6,Analysis!$C$37:$J$37,0)))/SQRT(B6) -> 0.070149288 | R6: =AVERAGE(INDEX(Analysis!$C$44:$J$49,0,MATCH($A6,Analysis!$C$37:$J$37,0))) -> 4.401204 | S6: =STDEV(INDEX(Analysis!$C$44:$J$49,0,MATCH($A6,Analysis!$C$37:$J$37,0)))/SQRT(C6) -> 0.33901349 | T6: =LOG(R6/P6,2) -> 2.1225789 | V6: =A6 -> CXCL8 | W6: =P6 -> 1.0106752 | X6: =R6 -> 4.401204 | Y6: =Q6 -> 0.070149288 | Z6: =S6 -> 0.33901349 | AB6: =A6 -> CXCL8 | AC6: =T6 -> 2.1225789
A7: TNF | B7: =COUNTIF(Analysis!$B$20:$B$31,"Control") -> 6 | C7: =COUNTIF(Analysis!$B$20:$B$31,"Treatment") -> 6 | D7: =SUM(INDEX(Analysis!$C$53:$J$58,0,MATCH($A7,Analysis!$C$52:$J$52,0))) -> 57 | E7: =D7-B7*(B7+1)/2 -> 36 | F7: =B7*C7-E7 -> 0 | G7: =MIN(E7,F7) -> 0 | H7: =B7*C7/2 -> 18 | I7: =SQRT(B7*C7*(B7+C7+1)/12) -> 6.244998 | J7: =(G7-H7-0.5*SIGN(G7-H7))/I7 -> -2.8022427 | K7: =2*(1-_xlfn.NORM.S.DIST(ABS(J7),TRUE)) -> 0.0050748681 | L7: =_xlfn.RANK.EQ(K7,$K$5:$K$12,1)+COUNTIF($K$5:K7,K7)-1 -> 3 | M7: =K7*8/L7 -> 0.013532982 | N7: =_xlfn.MINIFS($M$5:$M$12,$L$5:$L$12,">="&L7) -> 0.0067664908 | O7: =IF(N7<0.001,"***",IF(N7<0.01,"**",IF(N7<0.05,"*","ns"))) -> ** | P7: =AVERAGE(INDEX(Analysis!$C$38:$J$43,0,MATCH($A7,Analysis!$C$37:$J$37,0))) -> 1.0396373 | Q7: =STDEV(INDEX(Analysis!$C$38:$J$43,0,MATCH($A7,Analysis!$C$37:$J$37,0)))/SQRT(B7) -> 0.12239712 | R7: =AVERAGE(INDEX(Analysis!$C$44:$J$49,0,MATCH($A7,Analysis!$C$37:$J$37,0))) -> 2.4273116 | S7: =STDEV(INDEX(Analysis!$C$44:$J$49,0,MATCH($A7,Analysis!$C$37:$J$37,0)))/SQRT(C7) -> 0.24874066 | T7: =LOG(R7/P7,2) -> 1.223279 | V7: =A7 -> TNF | W7: =P7 -> 1.0396373 | X7: =R7 -> 2.4273116 | Y7: =Q7 -> 0.12239712 | Z7: =S7 -> 0.24874066 | AB7: =A7 -> TNF | AC7: =T7 -> 1.223279
A8: NFKB1 | B8: =COUNTIF(Analysis!$B$20:$B$31,"Control") -> 6 | C8: =COUNTIF(Analysis!$B$20:$B$31,"Treatment") -> 6 | D8: =SUM(INDEX(Analysis!$C$53:$J$58,0,MATCH($A8,Analysis!$C$52:$J$52,0))) -> 49 | E8: =D8-B8*(B8+1)/2 -> 28 | F8: =B8*C8-E8 -> 8 | G8: =MIN(E8,F8) -> 8 | H8: =B8*C8/2 -> 18 | I8: =SQRT(B8*C8*(B8+C8+1)/12) -> 6.244998 | J8: =(G8-H8-0.5*SIGN(G8-H8))/I8 -> -1.5212175 | K8: =2*(1-_xlfn.NORM.S.DIST(ABS(J8),TRUE)) -> 0.12820528 | L8: =_xlfn.RANK.EQ(K8,$K$5:$K$12,1)+COUNTIF($K$5:K8,K8)-1 -> 8 | M8: =K8*8/L8 -> 0.12820528 | N8: =_xlfn.MINIFS($M$5:$M$12,$L$5:$L$12,">="&L8) -> 0.12820528 | O8: =IF(N8<0.001,"***",IF(N8<0.01,"**",IF(N8<0.05,"*","ns"))) -> ns | P8: =AVERAGE(INDEX(Analysis!$C$38:$J$43,0,MATCH($A8,Analysis!$C$37:$J$37,0))) -> 1.0132851 | Q8: =STDEV(INDEX(Analysis!$C$38:$J$43,0,MATCH($A8,Analysis!$C$37:$J$37,0)))/SQRT(B8) -> 0.070164439 | R8: =AVERAGE(INDEX(Analysis!$C$44:$J$49,0,MATCH($A8,Analysis!$C$37:$J$37,0))) -> 1.4428678 | S8: =STDEV(INDEX(Analysis!$C$44:$J$49,0,MATCH($A8,Analysis!$C$37:$J$37,0)))/SQRT(C8) -> 0.24471034 | T8: =LOG(R8/P8,2) -> 0.50989892 | V8: =A8 -> NFKB1 | W8: =P8 -> 1.0132851 | X8: =R8 -> 1.4428678 | Y8: =Q8 -> 0.070164439 | Z8: =S8 -> 0.24471034 | AB8: =A8 -> NFKB1 | AC8: =T8 -> 0.50989892
A9: STAT3 | B9: =COUNTIF(Analysis!$B$20:$B$31,"Control") -> 6 | C9: =COUNTIF(Analysis!$B$20:$B$31,"Treatment") -> 6 | D9: =SUM(INDEX(Analysis!$C$53:$J$58,0,MATCH($A9,Analysis!$C$52:$J$52,0))) -> 57 | E9: =D9-B9*(B9+1)/2 -> 36 | F9: =B9*C9-E9 -> 0 | G9: =MIN(E9,F9) -> 0 | H9: =B9*C9/2 -> 18 | I9: =SQRT(B9*C9*(B9+C9+1)/12) -> 6.244998 | J9: =(G9-H9-0.5*SIGN(G9-H9))/I9 -> -2.8022427 | K9: =2*(1-_xlfn.NORM.S.DIST(ABS(J9),TRUE)) -> 0.0050748681 | L9: =_xlfn.RANK.EQ(K9,$K$5:$K$12,1)+COUNTIF($K$5:K9,K9)-1 -> 4 | M9: =K9*8/L9 -> 0.010149736 | N9: =_xlfn.MINIFS($M$5:$M$12,$L$5:$L$12,">="&L9) -> 0.0067664908 | O9: =IF(N9<0.001,"***",IF(N9<0.01,"**",IF(N9<0.05,"*","ns"))) -> ** | P9: =AVERAGE(INDEX(Analysis!$C$38:$J$43,0,MATCH($A9,Analysis!$C$37:$J$37,0))) -> 1.0038827 | Q9: =STDEV(INDEX(Analysis!$C$38:$J$43,0,MATCH($A9,Analysis!$C$37:$J$37,0)))/SQRT(B9) -> 0.039661362 | R9: =AVERAGE(INDEX(Analysis!$C$44:$J$49,0,MATCH($A9,Analysis!$C$37:$J$37,0))) -> 1.732647 | S9: =STDEV(INDEX(Analysis!$C$44:$J$49,0,MATCH($A9,Analysis!$C$37:$J$37,0)))/SQRT(C9) -> 0.21011974 | T9: =LOG(R9/P9,2) -> 0.78738697 | V9: =A9 -> STAT3 | W9: =P9 -> 1.0038827 | X9: =R9 -> 1.732647 | Y9: =Q9 -> 0.039661362 | Z9: =S9 -> 0.21011974 | AB9: =A9 -> STAT3 | AC9: =T9 -> 0.78738697
A10: MYC | B10: =COUNTIF(Analysis!$B$20:$B$31,"Control") -> 6 | C10: =COUNTIF(Analysis!$B$20:$B$31,"Treatment") -> 6 | D10: =SUM(INDEX(Analysis!$C$53:$J$58,0,MATCH($A10,Analysis!$C$52:$J$52,0))) -> 57 | E10: =D10-B10*(B10+1)/2 -> 36 | F10: =B10*C10-E10 -> 0 | G10: =MIN(E10,F10) -> 0 | H10: =B10*C10/2 -> 18 | I10: =SQRT(B10*C10*(B10+C10+1)/12) -> 6.244998 | J10: =(G10-H10-0.5*SIGN(G10-H10))/I10 -> -2.8022427 | K10: =2*(1-_xlfn.NORM.S.DIST(ABS(J10),TRUE)) -> 0.0050748681 | L10: =_xlfn.RANK.EQ(K10,$K$5:$K$12,1)+COUNTIF($K$5:K10,K10)-1 -> 5 | M10: =K10*8/L10 -> 0.008119789 | N10: =_xlfn.MINIFS($M$5:$M$12,$L$5:$L$12,">="&L10) -> 0.0067664908 | O10: =IF(N10<0.001,"***",IF(N10<0.01,"**",IF(N10<0.05,"*","ns"))) -> ** | P10: =AVERAGE(INDEX(Analysis!$C$38:$J$43,0,MATCH($A10,Analysis!$C$37:$J$37,0))) -> 1.0337345 | Q10: =STDEV(INDEX(Analysis!$C$38:$J$43,0,MATCH($A10,Analysis!$C$37:$J$37,0)))/SQRT(B10) -> 0.11594958 | R10: =AVERAGE(INDEX(Analysis!$C$44:$J$49,0,MATCH($A10,Analysis!$C$37:$J$37,0))) -> 2.1156681 | S10: =STDEV(INDEX(Analysis!$C$44:$J$49,0,MATCH($A10,Analysis!$C$37:$J$37,0)))/SQRT(C10) -> 0.070026427 | T10: =LOG(R10/P10,2) -> 1.0332477 | V10: =A10 -> MYC | W10: =P10 -> 1.0337345 | X10: =R10 -> 2.1156681 | Y10: =Q10 -> 0.11594958 | Z10: =S10 -> 0.070026427 | AB10: =A10 -> MYC | AC10: =T10 -> 1.0332477
A11: CDKN1A | B11: =COUNTIF(Analysis!$B$20:$B$31,"Control") -> 6 | C11: =COUNTIF(Analysis!$B$20:$B$31,"Treatment") -> 6 | D11: =SUM(INDEX(Analysis!$C$53:$J$58,0,MATCH($A11,Analysis!$C$52:$J$52,0))) -> 21 | E11: =D11-B11*(B11+1)/2 -> 0 | F11: =B11*C11-E11 -> 36 | G11: =MIN(E11,F11) -> 0 | H11: =B11*C11/2 -> 18 | I11: =SQRT(B11*C11*(B11+C11+1)/12) -> 6.244998 | J11: =(G11-H11-0.5*SIGN(G11-H11))/I11 -> -2.8022427 | K11: =2*(1-_xlfn.NORM.S.DIST(ABS(J11),TRUE)) -> 0.0050748681 | L11: =_xlfn.RANK.EQ(K11,$K$5:$K$12,1)+COUNTIF($K$5:K11,K11)-1 -> 6 | M11: =K11*8/L11 -> 0.0067664908 | N11: =_xlfn.MINIFS($M$5:$M$12,$L$5:$L$12,">="&L11) -> 0.0067664908 | O11: =IF(N11<0.001,"***",IF(N11<0.01,"**",IF(N11<0.05,"*","ns"))) -> ** | P11: =AVERAGE(INDEX(Analysis!$C$38:$J$43,0,MATCH($A11,Analysis!$C$37:$J$37,0))) -> 1.0080073 | Q11: =STDEV(INDEX(Analysis!$C$38:$J$43,0,MATCH($A11,Analysis!$C$37:$J$37,0)))/SQRT(B11) -> 0.055322427 | R11: =AVERAGE(INDEX(Analysis!$C$44:$J$49,0,MATCH($A11,Analysis!$C$37:$J$37,0))) -> 0.31122485 | S11: =STDEV(INDEX(Analysis!$C$44:$J$49,0,MATCH($A11,Analysis!$C$37:$J$37,0)))/SQRT(C11) -> 0.035183771 | T11: =LOG(R11/P11,2) -> -1.6954769 | V11: =A11 -> CDKN1A | W11: =P11 -> 1.0080073 | X11: =R11 -> 0.31122485 | Y11: =Q11 -> 0.055322427 | Z11: =S11 -> 0.035183771 | AB11: =A11 -> CDKN1A | AC11: =T11 -> -1.6954769
A12: BAX | B12: =COUNTIF(Analysis!$B$20:$B$31,"Control") -> 6 | C12: =COUNTIF(Analysis!$B$20:$B$31,"Treatment") -> 6 | D12: =SUM(INDEX(Analysis!$C$53:$J$58,0,MATCH($A12,Analysis!$C$52:$J$52,0))) -> 22 | E12: =D12-B12*(B12+1)/2 -> 1 | F12: =B12*C12-E12 -> 35 | G12: =MIN(E12,F12) -> 1 | H12: =B12*C12/2 -> 18 | I12: =SQRT(B12*C12*(B12+C12+1)/12) -> 6.244998 | J12: =(G12-H12-0.5*SIGN(G12-H12))/I12 -> -2.6421145 | K12: =2*(1-_xlfn.NORM.S.DIST(ABS(J12),TRUE)) -> 0.0082390188 | L12: =_xlfn.RANK.EQ(K12,$K$5:$K$12,1)+COUNTIF($K$5:K12,K12)-1 -> 7 | M12: =K12*8/L12 -> 0.0094160215 | N12: =_xlfn.MINIFS($M$5:$M$12,$L$5:$L$12,">="&L12) -> 0.0094160215 | O12: =IF(N12<0.001,"***",IF(N12<0.01,"**",IF(N12<0.05,"*","ns"))) -> ** | P12: =AVERAGE(INDEX(Analysis!$C$38:$J$43,0,MATCH($A12,Analysis!$C$37:$J$37,0))) -> 1.0190978 | Q12: =STDEV(INDEX(Analysis!$C$38:$J$43,0,MATCH($A12,Analysis!$C$37:$J$37,0)))/SQRT(B12) -> 0.089593618 | R12: =AVERAGE(INDEX(Analysis!$C$44:$J$49,0,MATCH($A12,Analysis!$C$37:$J$37,0))) -> 0.49585941 | S12: =STDEV(INDEX(Analysis!$C$44:$J$49,0,MATCH($A12,Analysis!$C$37:$J$37,0)))/SQRT(C12) -> 0.075456775 | T12: =LOG(R12/P12,2) -> -1.0392894 | V12: =A12 -> BAX | W12: =P12 -> 1.0190978 | X12: =R12 -> 0.49585941 | Y12: =Q12 -> 0.089593618 | Z12: =S12 -> 0.075456775 | AB12: =A12 -> BAX | AC12: =T12 -> -1.0392894
